<?xml version='1.0' encoding='utf-8'?>
<robot xmlns:drake="http://drake.mit.edu" name="slip_stick_rig">
  <material name="leg_red">
    <color rgba="0.22745098039215686 0.6313725490196078 0.9254901960784314 1.0" />
  </material>
  <material name="toe_heel_blue">
    <color rgba="1.0 0.5843137254901961 0.2196078431372549 1.0" />
  </material>
  <material name="sole_green">
    <color rgba="1.0 0.8627450980392157 0.0 1.0" />
  </material>
  <material name="mass_gray">
    <color rgba="0.2196078431372549 0.2196078431372549 0.2196078431372549 0.75" />
  </material>
  <link name="world" />
  <link name="x_stage" />
  <link name="z_stage" />
  <joint name="world_to_x_prismatic" type="prismatic">
    <parent link="world" />
    <child link="x_stage" />
    <origin xyz="0 0 0" rpy="0 0 0" />
    <axis xyz="1 0 0" />
    <limit lower="0.0" upper="1.5" effort="1e6" velocity="5.0" />
  </joint>
  <joint name="x_to_z_prismatic" type="prismatic">
    <parent link="x_stage" />
    <child link="z_stage" />
    <origin xyz="0 0 0" rpy="0 0 0" />
    <axis xyz="0 0 1" />
    <limit lower="-0.7" upper="-0.0" effort="1e6" velocity="5.0" />
  </joint>
  <link name="leg">
    <inertial>
      <origin xyz="0 0 0" rpy="0 0 0" />
      <mass value="0.15" />
      <inertia ixx="0.00113" ixy="0" ixz="0" iyy="0.00113" iyz="0" izz="9.999999999999999e-06" />
    </inertial>
    <visual>
      <origin xyz="0.0 0.0 0.0" rpy="0.0 0.0 0.0" />
      <geometry>
        <box size="0.02 0.02 0.3" />
      </geometry>
      <material name="leg_red" />
    </visual>
    <visual>
      <origin xyz="0.0 0.0 -0.15" rpy="1.5707963267948966 0.0 0.0" />
      <geometry>
        <cylinder radius="0.01" length="0.02" />
      </geometry>
      <material name="leg_red" />
    </visual>
  </link>
  <joint name="z_to_leg_fixed" type="fixed">
    <parent link="z_stage" />
    <child link="leg" />
    <origin xyz="0 0 0.15" rpy="0 0 0" />
  </joint>
  <link name="mass">
    <inertial>
      <origin xyz="0 0 0" rpy="0 0 0" />
      <mass value="2.0" />
      <inertia ixx="0.0006272" ixy="0" ixz="0" iyy="0.0006272" iyz="0" izz="0.0006272" />
    </inertial>
    <visual>
      <origin xyz="0.0 0.0 0.0" rpy="0.0 0.0 0.0" />
      <geometry>
        <sphere radius="0.027999999999999997" />
      </geometry>
      <material name="mass_gray" />
    </visual>
  </link>
  <joint name="leg_to_mass_weld" type="fixed">
    <parent link="leg" />
    <child link="mass" />
    <origin xyz="0 0 0.15" rpy="0 0 0" />
  </joint>
  <link name="foot">
    <inertial>
      <origin xyz="-0.0 -0.0 -0.02" rpy="0 0 0" />
      <mass value="0.075" />
      <inertia ixx="1.588286290322581e-05" ixy="0" ixz="0" iyy="5.501592741935485e-05" iyz="0" izz="7.038306451612905e-05" />
    </inertial>
    <visual>
      <origin xyz="0.04 -0.0 -0.02" rpy="0.0 0.0 0.0" />
      <geometry>
        <box size="0.02 0.05 0.005" />
      </geometry>
      <material name="toe_heel_blue" />
    </visual>
    <collision>
      <origin xyz="0.04 -0.0 -0.02" rpy="0.0 0.0 0.0" />
      <geometry>
        <box size="0.02 0.05 0.005" />
      </geometry>
      <drake:proximity_properties>
        <drake:rigid_hydroelastic />
        <drake:mesh_resolution_hint value="0.005" />
        <drake:mu_static value="0.9" />
        <drake:mu_dynamic value="0.8" />
        <drake:hunt_crossley_dissipation value="1.0" />
      </drake:proximity_properties>
    </collision>
    <visual>
      <origin xyz="-0.04 -0.0 -0.02" rpy="0.0 0.0 0.0" />
      <geometry>
        <box size="0.02 0.05 0.005" />
      </geometry>
      <material name="toe_heel_blue" />
    </visual>
    <collision>
      <origin xyz="-0.04 -0.0 -0.02" rpy="0.0 0.0 0.0" />
      <geometry>
        <box size="0.02 0.05 0.005" />
      </geometry>
      <drake:proximity_properties>
        <drake:rigid_hydroelastic />
        <drake:mesh_resolution_hint value="0.005" />
        <drake:mu_static value="0.9" />
        <drake:mu_dynamic value="0.8" />
        <drake:hunt_crossley_dissipation value="1.0" />
      </drake:proximity_properties>
    </collision>
    <visual>
      <origin xyz="-0.0 -0.0 -0.02" rpy="0.0 0.0 0.0" />
      <geometry>
        <box size="0.060000000000000005 0.05 0.007" />
      </geometry>
      <material name="sole_green" />
    </visual>
    <collision>
      <origin xyz="-0.0 -0.0 -0.02" rpy="0.0 0.0 0.0" />
      <geometry>
        <box size="0.060000000000000005 0.05 0.007" />
      </geometry>
      <drake:proximity_properties>
        <drake:compliant_hydroelastic />
        <drake:hydroelastic_modulus value="5000000.0" />
        <drake:mesh_resolution_hint value="0.005" />
        <drake:mu_static value="0.9" />
        <drake:mu_dynamic value="0.8" />
        <drake:hunt_crossley_dissipation value="1.0" />
      </drake:proximity_properties>
    </collision>
  </link>
  <joint name="ankle_y" type="revolute">
    <parent link="leg" />
    <child link="foot" />
    <origin xyz="0 0 -0.15" rpy="0 0 0" />
    <axis xyz="0 1 0" />
    <limit lower="-1.0471975511965976" upper="1.0471975511965976" effort="50" velocity="10" />
  </joint>
</robot>